Workbook

Sheet コスト表
B1: 1コス=1時間
B2: 分類 | C2: タスク | D2: コスト(時間) | E2: 優先度 | F2: 制作段階 | G2: 進捗 | H2: 備考
B3: プレイヤー | C3: ジャンプ時の画面効果 | D3: 0.5 | E3: S | F3: 10月 | G3: 完了
B4: プレイヤー | C4: 死亡演出 | D4: 0.5 | E4: A | F4: 10月 | G4: 完了
B5: プレイヤー | C5: エフェクト | D5: 4 | E5: S | F5: 10月 | G5: 完了
B6: プレイヤー | C6: 方向インジケーター | D6: 2 | E6: S | F6: 10月 | G6: 完了
B7: プレイヤー | C7: 武器切り替え | D7: 4 | E7: S | F7: 11月 | G7: 完了
B8: プレイヤー | C8: 武器切り替えアニメーション | D8: 0.5 | E8: S | F8: 11月 | G8: 完了
B9: プレイヤー | C9: クロスヘア | D9: 0.5 | E9: A | F9: 10月 | G9: 完了
B10: プレイヤー | C10: サウンド | D10: 1 | E10: S | F10: 12月 | G10: 作業中
B11: プレイヤー | C11: 剣から盾にモデル変更 | D11: 0.5 | E11: S | F11: 11月 | G11: 完了
B12: プレイヤー | C12: ガード実装 | D12: 1 | E12: S | F12: 11月 | G12: 完了
B13: プレイヤー | C13: 耐久値実装 | D13: 1 | E13: S | F13: 11月 | G13: 完了
B14: プレイヤー | C14: タックル攻撃アニメーション | D14: 0.5 | E14: S | G14: 完了
B15: プレイヤー | C15: 死亡アニメーション | D15: 0.5 | E15: S | G15: 完了
B16: プレイヤー | C16: 待機アニメーション | D16: 0.5 | E16: S | G16: 完了
B18: 敵ベース | C18: 当たり判定処理 | D18: 5 | E18: S | G18: 完了 | H18: プレイヤーの弾や攻撃を受ける処理
B19: 敵ベース | C19: 状態管理 | D19: 4 | E19: S | G19: 完了 | H19: 移動、攻撃、死亡などの状態管理
B20: 敵ベース | C20: ナビゲーション・移動処理 | D20: 6 | E20: S | G20: 完了 | H20: プレイヤー追尾処理は実装済みなのでいったん完了とす、壁回避(未完)
B21: 敵ベース | C21: アイテムドロップ | D21: 2 | E21: S | G21: 完了
B22: 敵ベース | C22: アニメーション制御 | D22: 4 | E22: S | G22: 完了 | H22: 状態に応じたアニメーション切り替え
B23: 敵ベース | C23: エフェクト管理 | D23: 3 | E23: S | G23: 作業中
B24: 敵ベース | C24: サウンド管理 | D24: 3 | E24: S | G24: 作業中
B26: 敵1(通常ゾンビ) | C26: 近接攻撃実装 | D26: 1.5 | E26: S | G26: 完了
B27: 敵1(通常ゾンビ) | C27: 移動速度調整 | D27: 1 | E27: S | G27: 完了
B28: 敵1(通常ゾンビ) | C28: アニメーション実装 | D28: 2 | E28: S | G28: 完了
B29: 敵1(通常ゾンビ) | C29: エフェクト実装 | D29: 2 | E29: S | G29: 完了
B30: 敵1(通常ゾンビ) | C30: 当たり判定実装 | D30: 3 | E30: S | G30: 完了
B31: 敵1(通常ゾンビ) | C31: サウンド実装 | D31: 1 | E31: S | G31: 作業中
B33: 敵2(ランナーゾンビ) | C33: ダッシュ機能実装 | D33: 1 | E33: S | G33: 完了
B34: 敵2(ランナーゾンビ) | C34: 近接攻撃実装 | D34: 1.5 | E34: S | G34: 完了
B35: 敵2(ランナーゾンビ) | C35: アニメーション実装 | D35: 2 | E35: S | G35: 完了
B36: 敵2(ランナーゾンビ) | C36: エフェクト実装 | D36: 2 | E36: S | G36: 完了
... B49: ボス(ゾンビを召喚) | C49: 移動速度調整 | D49: 1 | E49: S | G49: 完了
B50: ボス(ゾンビを召喚) | C50: プレイヤー検知(視野 or 範囲) | D50: 5 | E50: S | G50: 完了 | H50: 視野角や距離で検知する仕組み
B51: ボス(ゾンビを召喚) | C51: アニメーション実装 | D51: 3 | E51: S | G51: 作業中
B52: ボス(ゾンビを召喚) | C52: エフェクト実装 | D52: 2 | E52: S | G52: 作業中
B53: ボス(ゾンビを召喚) | C53: 当たり判定実装 | D53: 3 | E53: S | G53: 完了
B54: ボス(ゾンビを召喚) | C54: サウンド実装 | D54: 1 | E54: S | G54: 作業中
B56: マップ | C56: マップ設計 | D56: 2 | E56: S | G56: 完了
...

Sheet 集計
B2: 分類 | C2: コスト合計 | D2: 完了コスト | E2: 作業中コスト | F2: 未着手コスト | G2: 進捗率 (%) | I2: 総コスト | J2: =SUM(C:C) -> 160.5
B3: プレイヤー | C3: =SUMIF(コスト表!B:B, B3, コスト表!D:D) -> 17 | D3: =SUMIFS(コスト表!D:D, コスト表!B:B, "プレイヤー", コスト表!G:G, "完了") -> 16 | E3: =SUMIFS(コスト表!D:D, コスト表!B:B, "プレイヤー", コスト表!G:G, "作業中") -> 1 | F3: =SUMIFS(コスト表!D:D, コスト表!B:B, "プレイヤー", コスト表!G:G, "未着手") -> 0 | G3: =ROUNDDOWN(COUNTIFS(コスト表!B:B, "プレイヤー", コスト表!G:G, "完了") / COUNTIF(コスト表!B:B, "プレイヤー") * 100,1) -> 92.8 | I3: 消化コスト | J3: =SUMIF(コスト表!G:G,"完了",コスト表!D:D) -> 127 | K3: 消費コスト / 日数
B4: 敵ベース | C4: =SUMIF(コスト表!B:B, B4, コスト表!D:D) -> 27 | D4: =SUMIFS(コスト表!D:D, コスト表!B:B, "敵ベース", コスト表!G:G, "完了") -> 21 | E4: =SUMIFS(コスト表!D:D, コスト表!B:B, "敵ベース", コスト表!G:G, "作業中") -> 6 | F4: =SUMIFS(コスト表!D:D, コスト表!B:B, "敵ベース", コスト表!G:G, "未着手") -> 0 | G4: =ROUNDDOWN(COUNTIFS(コスト表!B:B, "敵ベース", コスト表!G:G, "完了") / COUNTIF(コスト表!B:B, "敵ベース") * 100,1) -> 71.4 | I4: 現在の日数(土日除く) | J4: =NETWORKDAYS(J5,J6) -> 90 | K4: =ROUNDDOWN(J3 / J4,1) -> 1.4
B5: 敵1(通常ゾンビ) | C5: =SUMIF(コスト表!B:B, B5, コスト表!D:D) -> 10.5 | D5: =SUMIFS(コスト表!D:D, コスト表!B:B, "敵1(通常ゾンビ)", コスト表!G:G, "完了") -> 9.5 | E5: =SUMIFS(コスト表!D:D, コスト表!B:B, "敵1(通常ゾンビ)", コスト表!G:G, "作業中") -> 1 | F5: =SUMIFS(コスト表!D:D, コスト表!B:B, "敵1(通常ゾンビ)", コスト表!G:G, "未着手") -> 0 | G5: =ROUNDDOWN(COUNTIFS(コスト表!B:B, "敵1(通常ゾンビ)", コスト表!G:G, "完了") / COUNTIF(コスト表!B:B, "敵1(通常ゾンビ)") * 100,1) -> 83.3 | I5: 開始日 | J5: =DATE(2025,10,1) -> 45931
B6: 敵2(ランナーゾンビ) | C6: =SUMIF(コスト表!B:B, B6, コスト表!D:D) -> 10.5 | D6: =SUMIFS(コスト表!D:D, コスト表!B:B, "敵2(ランナーゾンビ)", コスト表!G:G, "完了") -> 9.5 | E6: =SUMIFS(コスト表!D:D, コスト表!B:B, "敵2(ランナーゾンビ)", コスト表!G:G, "作業中") -> 1 | F6: =SUMIFS(コスト表!D:D,コスト表!B:B,"敵2(ランナーゾンビ)",コスト表!G:G,"未着手") -> 0 | G6: =ROUNDDOWN(COUNTIFS(コスト表!B:B, "敵2(ランナーゾンビ)", コスト表!G:G, "完了") / COUNTIF(コスト表!B:B, "敵2(ランナーゾンビ)") * 100,1) -> 83.3 | I6: 今日の日付 | J6: =TODAY() -> 46056
B7: 敵3(遠距離型ゾンビ) | C7: =SUMIF(コスト表!B:B, B7, コスト表!D:D) -> 10.5 | D7: =SUMIFS(コスト表!D:D, コスト表!B:B, "敵3(遠距離型ゾンビ)", コスト表!G:G, "完了") -> 9.5 | E7: =SUMIFS(コスト表!D:D, コスト表!B:B, "敵3(遠距離型ゾンビ)", コスト表!G:G, "作業中") -> 1 | F7: =SUMIFS(コスト表!D:D, コスト表!B:B, "敵3(遠距離型ゾンビ)", コスト表!G:G, "未着手") -> 0 | G7: =ROUNDDOWN(COUNTIFS(コスト表!B:B, "敵3(遠距離型ゾンビ)", コスト表!G:G, "完了") / COUNTIF(コスト表!B:B, "敵3(遠距離型ゾンビ)") * 100,1) -> 83.3
B8: ボス(ゾンビを召喚) | C8: =SUMIF(コスト表!B:B, B8, コスト表!D:D) -> 24 | D8: =SUMIFS(コスト表!D:D, コスト表!B:B, "ボス(ゾンビを召喚)", コスト表!G:G, "完了") -> 14 | E8: =SUMIFS(コスト表!D:D, コスト表!B:B, "ボス(ゾンビを召喚)", コスト表!G:G, "作業中") -> 6 | F8: =SUMIFS(コスト表!D:D,コスト表!B:B,"ボス(ゾンビを召喚)",コスト表!G:G,"未着手") -> 4 | G8: =ROUNDDOWN(COUNTIFS(コスト表!B:B, "ボス(ゾンビを召喚)", コスト表!G:G, "完了") / COUNTIF(コスト表!B:B, "ボス(ゾンビを召喚)") * 100,1) -> 50 | I8: 制作段階 | J8: コスト合計 | K8: 完了コスト | L8: 進捗率(%)
B9: マップ | C9: =SUMIF(コスト表!B:B, B9, コスト表!D:D) -> 8 | D9: =SUMIFS(コスト表!D:D, コスト表!B:B, "マップ", コスト表!G:G, "完了") -> 8 | E9: =SUMIFS(コスト表!D:D, コスト表!B:B, "マップ", コスト表!G:G, "作業中") -> 0 | F9: =SUMIFS(コスト表!D:D, コスト表!B:B, "マップ", コスト表!G:G, "未着手") -> 0 | G9: =ROUNDDOWN(COUNTIFS(コスト表!B:B, "マップ", コスト表!G:G, "完了") / COUNTIF(コスト表!B:B, "マップ") * 100,1) -> 100 | I9: 10月
B10: ウェーブ管理 | C10: =SUMIF(コスト表!B:B, B10, コスト表!D:D) -> 27 | D10: =SUMIFS(コスト表!D:D, コスト表!B:B, "ウェーブ管理", コスト表!G:G, "完了") -> 21 | E10: =SUMIFS(コスト表!D:D, コスト表!B:B, "ウェーブ管理", コスト表!G:G, "作業中") -> 0 | F10: =SUMIFS(コスト表!D:D, コスト表!B:B, "ウェーブ管理", コスト表!G:G, "未着手") -> 6 | G10: =ROUNDDOWN(COUNTIFS(コスト表!B:B, "ウェーブ管理", コスト表!G:G, "完了") / COUNTIF(コスト表!B:B, "ウェーブ管理") * 100,1) -> 87.5 | I10: 11月 | J10: =SUMIF(コスト表!F:F, "プロト", コスト表!D:D) -> 0 | K10: =SUMIFS(コスト表!D:D, コスト表!F:F, "プロト", コスト表!G:G, "完了") -> 0 | L10: =ROUNDDOWN(COUNTIFS(コスト表!F:F, "プロト", コスト表!G:G, "完了") / COUNTIF(コスト表!F:F, "プロト") * 100,1) -> #DIV/0!
B11: アイテム | C11: =SUMIF(コスト表!B:B, B11, コスト表!D:D) -> 8.5 | D11: =SUMIFS(コスト表!D:D, コスト表!B:B, "アイテム", コスト表!G:G, "完了") -> 8.5 | E11: =SUMIFS(コスト表!D:D, コスト表!B:B, "アイテム", コスト表!G:G, "作業中") -> 0 | F11: =SUMIFS(コスト表!D:D, コスト表!B:B, "アイテム", コスト表!G:G, "未着手") -> 0 | G11: =ROUNDDOWN(COUNTIFS(コスト表!B:B, "アイテム", コスト表!G:G, "完了") / COUNTIF(コスト表!B:B, "アイテム") * 100,1) -> 100 | I11: 12月 | J11: =SUMIF(コスト表!F:F, "アルファ", コスト表!D:D) -> 0 | K11: =SUMIFS(コスト表!D:D, コスト表!F:F, "アルファ", コスト表!G:G, "完了") -> 0 | L11: =ROUNDDOWN(COUNTIFS(コスト表!F:F, "アルファ", コスト表!G:G, "完了") / COUNTIF(コスト表!F:F, "アルファ") * 100,1) -> #DIV/0!
B12: タイトル | C12: =SUMIF(コスト表!B:B, B12, コスト表!D:D) -> 4 | D12: =SUMIFS(コスト表!D:D, コスト表!B:B, "タイトル", コスト表!G:G, "完了") -> 4 | E12: =SUMIFS(コスト表!D:D, コスト表!B:B, "タイトル", コスト表!G:G, "作業中") -> 0 | F12: =SUMIFS(コスト表!D:D, コスト表!B:B, "タイトル", コスト表!G:G, "未着手") -> 0 | G12: =ROUNDDOWN(COUNTIFS(コスト表!B:B, "タイトル", コスト表!G:G, "完了") / COUNTIF(コスト表!B:B, "タイトル") * 100,1) -> 100 | I12: 1月 | J12: =SUMIF(コスト表!F:F, "ベータ", コスト表!D:D) -> 0 | K12: =SUMIFS(コスト表!D:D, コスト表!F:F, "ベータ", コスト表!G:G, "完了") -> 0 | L12: =ROUNDDOWN(COUNTIFS(コスト表!F:F, "ベータ", コスト表!G:G, "完了") / COUNTIF(コスト表!F:F, "ベータ") * 100,1) -> #DIV/0!
B13: リザルト | C13: =SUMIF(コスト表!B:B, B13, コスト表!D:D) -> 4 | D13: =SUMIFS(コスト表!D:D, コスト表!B:B, "リザルト", コスト表!G:G, "完了") -> 3 | E13: =SUMIFS(コスト表!D:D, コスト表!B:B, "リザルト", コスト表!G:G, "作業中") -> 0 | F13: =SUMIFS(コスト表!D:D, コスト表!B:B, "リザルト", コスト表!G:G, "未着手") -> 1 | G13: =ROUNDDOWN(COUNTIFS(コスト表!B:B, "リザルト", コスト表!G:G, "完了") / COUNTIF(コスト表!B:B, "リザルト") * 100,1) -> 80
B14: オプション | C14: =SUMIF(コスト表!B:B, B14, コスト表!D:D) -> 6.5 | D14: =SUMIFS(コスト表!D:D, コスト表!B:B, "オプション", コスト表!G:G, "完了") -> 0 | E14: =SUMIFS(コスト表!D:D, コスト表!B:B, "オプション", コスト表!G:G, "作業中") -> 0 | F14: =SUMIFS(コスト表!D:D,コスト表!B:B,"オプション",コスト表!G:G,"未着手") -> 6.5 | G14: =ROUNDDOWN(COUNTIFS(コスト表!B:B, "オプション", コスト表!G:G, "完了") / COUNTIF(コスト表!B:B, "オプション") * 100,1) -> 0
B15: ゲームオーバー | C15: =SUMIF(コスト表!B:B, B15, コスト表!D:D) -> 3 | D15: =SUMIFS(コスト表!D:D, コスト表!B:B, "ゲームオーバー", コスト表!G:G, "完了") -> 3 | E15: =SUMIFS(コスト表!D:D, コスト表!B:B, "ゲームオーバー", コスト表!G:G, "作業中") -> 0 | F15: =SUMIFS(コスト表!D:D, コスト表!B:B, "ゲームオーバー", コスト表!G:G, "未着手") -> 0 | G15: =ROUNDDOWN(COUNTIFS(コスト表!B:B, "ゲームオーバー", コスト表!G:G, "完了") / COUNTIF(コスト表!B:B, "ゲームオーバー") * 100,1) -> 100
B16: 合計進捗率 | G16: =ROUNDDOWN(COUNTIF(コスト表!G:G, "完了") / COUNTA(コスト表!G:G) * 100,1) -> 77.6

Sheet プルダウン用
B2: 進捗段階 | D2: 制作段階 | F2: 優先度
B3: 未着手 | D3: 10月 | F3: S
B4: 作業中 | D4: 11月 | F4: A
B5: 完了 | D5: 12月 | F5: B
B6: 削除 | D6: 1月 | F6: C
B8: 優先度
B9: S：実装が必須
B10: A：重要な要素
B11: B：なくても問題ないがあるといい
B12: C：なくても問題ない
